Workbook

Sheet README
A1: DuroMax / DuroStar Home Backup Spec Sheet
A2: Source: duromaxpower.com, scraped Sept 23-24, 2026. Values are exactly as the website states them; blank = not listed.
A3: Purpose: the data source for the 3D Home Backup Power simulator. Each tab maps to one data set in the app.
A5: Tabs
A6: Generators - 33 current models (28 DuroMax, 5 DuroStar). Excluded as discontinued: XP5500X, XP15000EH, DS13000E, DS13000EH, DS4500DX, DS4000WGE. watts/amps/runtime per fuel, outlets, neutral type (from owner's manuals) and switch requirement, engine, dimensions, links.
A7: Compatibility - which inlet box, cord, transfer switch and interlock breaker go with each generator outlet. The Generators tab looks these up by formula.
A8: Transfer Switches - 19 Reliance manual switches and kits (circuits, amps, breakers, inlet required).
A9: Interlock Kits - 13 GenInterlock kits by panel brand/series, main breaker size, throw direction, backfeed breaker position.
A10: Inlet Boxes - 10 power inlet boxes (50A CS6375, 30A L14-30, 20A L14-20, 120V L5-30).
A11: Cords & Adapters - 29 generator cords, adapters and replacement plugs.
A12: Soft Starters (AirGo) - 8 AirGo products; soft starters cut motor start-up current (site claim: up to 70%) so central AC / heat pumps / well pumps can start on a portable generator.
A13: Connection Guide - summary of the Home Power Backup Installation article (interlock vs transfer switch vs extension cords), for the app's explainer screens.
... A20: - To add a product, copy a row and fill the same columns. Keep Model / SKU unique - the app uses it as the key.

Sheet Generators
A1: Identity | J1: Gasoline | P1: Propane | W1: Natural Gas | AC1: Outlets | AK1: Home Connection (calc) | AT1: Neutral / Transfer Switch | AZ1: Engine | BJ1: Generator | BU1: Features | BX1: Reference
A2: Brand | B2: Model | C2: Product Title | D2: Generator Type | E2: Fuel Config | F2: EFI | G2: Price (USD) | H2: Sales Status | I2: Home Backup Use | J2: Starting W | K2: Running W | L2: 120V A | M2: 240V A | N2: Run hr @25% | O2: Run hr @50% | P2: Starting W | Q2: Running W | R2: 120V A | S2: 240V A | T2: Run hr @25% | U2: Run hr @50% | V2: Runtime Tank Basis | W2: Starting W | X2: Running W | Y2: 120V A | Z2: 240V A | AA2: Pressure (in. WC) | AB2: BTU @ Full Load | AC2: 5-20R | AD2: L5-30R | AE2: TT-30R | AF2: L14-30R | AG2: 14-50R | AH2: USB | AI2: 12V DC | AJ2: GFCI | AK2: Best 240V Outlet | AL2: Outlet Limit (W) | AM2: Max to Panel - Gas (W) | AN2: Max to Panel - LP (W) | AO2: Max to Panel - NG (W) | AP2: Matching Inlet Box | AQ2: Matching Cord | AR2: Matching Transfer Switches | AS2: Interlock Setup | AT2: Neutral (as shipped) | AU2: DuroMax Unbond Instructions | AV2: Switch / Interlock Requirement | AW2: Evidence | AX2: Owner's Manual | AY2: Unbond Instructions URL | AZ2: Engine Type | BA2: cc | BB2: RPM | BC2: Start Type | BD2: Remote Start | BE2: Oil Type | BF2: Oil (fl oz) | BG2: CO Shutdown | BH2: EPA | BI2: CARB | BJ2: Voltage | BK2: Hz | BL2: THD | BM2: AVR | BN2: Battery | BO2: Tank (gal) | BP2: Dimensions (in) | BQ2: Dry Wt (lb) | BR2: Wet Wt (lb) | BS2: Noise (dB) | BT2: Warranty | BU2: Parallel | BV2: Transfer Switch Ready | BW2: ECO / Variable Idle | BX2: Included Accessories | BY2: Product URL | BZ2: Image URL | CA2: Scrape Notes
A3: DuroMax | B3: XP4850EH | C3: 4,850 Watt Dual Fuel Portable Generator | D3: Conventional open frame | E3: Dual Fuel | F3: No | G3: 549 | H3: Amazon exclusive | I3: Yes | J3: 4850 | K3: 3850 | L3: 32.08 | M3: 16.04 | N3: 23 | O3: 10 | P3: 4608 | Q3: 3658 | R3: 30.48 | S3: 15.24 | T3: 18 | U3: 9 | AC3: 2 | AD3: 0 | AE3: 0 | AF3: 1 | AG3: 0 | AH3: 0 | AI3: 1 | AJ3: Yes | AK3: =IF(N(AG3)>0,"14-50R (50A)",IF(N(AF3)>0,"L14-30R (30A)","None - 120V only")) -> L14-30R (30A) | AL3: =INDEX(Compatibility!$C$2:$C$5,MATCH(AK3,Compatibility!$A$2:$A$5,0)) -> 7200 | AM3: =IF(ISNUMBER(K3),MIN(K3,AL3),"") -> 3850 | AN3: =IF(ISNUMBER(Q3),MIN(Q3,AL3),"") -> 3658 | AO3: =IF(ISNUMBER(X3),MIN(X3,AL3),"") | AP3: =INDEX(Compatibility!$D$2:$D$5,MATCH(AK3,Compatibility!$A$2:$A$5,0)) -> PB30, PBN30 (30A L14-30 inlet) | AQ3: =INDEX(Compatibility!$E$2:$E$5,MATCH(AK3,Compatibility!$A$2:$A$5,0)) -> XP3010GC, XP3025GC, XP3050GC, PC3040 (L14-30P to L14-30R) | AR3: =INDEX(Compatibility!$F$2:$F$5,MATCH(AK3,Compatibility!$A$2:$A$5,0)) -> 30A / 6 circuit: 306A, R306A (outdoor), 306C, 306D, 306CRK (kit); 30A / 10 circuit: 310C, 310D, 310CRK (kit), R310A (outdoor), 310CDKN (kit) | AS3: =INDEX(Compatibility!$G$2:$G$5,MATCH(AK3,Compatibility!$A$2:$A$5,0)) -> 30A 2-pole backfeed breaker (panel brand) + GenInterlock kit for panel | AT3: Floating | AU3: No | AV3: =IF(I3<>"Yes","120V only - extension cords / furnace switch",IF(AT3="Floating","Floating neutral: standard 2-pole transfer switch or interlock kit as-is",IF(AT3="Bonded",IF(AU3="Yes","Bonded neutral: have an electrician remove the bond (DuroMax instructions) for 2-pole switch / interlock, or use a neutral-switching (3-pole) switch","Bonded neutral, no unbond instructions published: neutral-switching (3-pole) switch - confirm with DuroMax"),"Neutral not stated - confirm with DuroMax"))) -> Floating neutral: standard 2-pole transfer switch or interlock kit as-is | AW3: "Neutral System Floating" (manual p.68) | AX3: https://cdn.shopify.com/s/files/1/0613/1168/0689/files/XP4850eh_manual_revised10042022_WEB.pdf | AZ3: 4-Stroke OHV | BA3: 210 | BB3: 3600 | BC3: Electric (rocker switch), recoil | BE3: 10W-30 | BF3: 20.3 | BH3: Yes | BI3: No | BJ3: 120/240V | BK3: 60 | BM3: Yes | BN3: 12V SLA (included) | BO3: 4 | BP3: 25 L x 24 W x 21 H | BQ3: 122 | BR3: 132 | BS3: 69 | BT3: 3 Year | BX3: Wheel & handle kit, propane hose & regulator (full list not stated) | BY3: https://www.duromaxpower.com/products/duromax-xp4850eh-4850-watt-dual-fuel-hybrid-generator-w-electric-start | BZ3: https://cdn.shopify.com/s/files/1/0613/1168/0689/products/XP4850EH_1.png?v=1749582793 | CA3: CO shutdown not listed (only automatic low oil shutdown). '50 State Emissions: No'. 12V = '12V Post'. MX2 Power Boost. 'Available Exclusively At' Amazon; .js available=false. THD not listed.
A4: DuroMax | B4: XP5500HX | C4: 5,500 Watt Dual Fuel Portable HX Generator w/ CO Alert | D4: Conventional open frame | E4: Dual Fuel | F4: No | G4: 629 | H4: In stock | I4: Yes | J4: 5500 | K4: 4500 | L4: 37.5 | M4: 18.75 | N4: 19 | O4: 9 | P4: 5225 | Q4: 4275 | R4: 35.63 | S4: 17.81 | T4: 15 | U4: 8 | AC4: 2 | AD4: 0 | AE4: 0 | AF4: 1 | AG4: 0 | AH4: 2 | AI4: 0 | AJ4: Yes | AK4: =IF(N(AG4)>0,"14-50R (50A)",IF(N(AF4)>0,"L14-30R (30A)","None - 120V only")) -> L14-30R (30A) | AL4: =INDEX(Compatibility!$C$2:$C$5,MATCH(AK4,Compatibility!$A$2:$A$5,0)) -> 7200 | AM4: =IF(ISNUMBER(K4),MIN(K4,AL4),"") -> 4500 | AN4: =IF(ISNUMBER(Q4),MIN(Q4,AL4),"") -> 4275 | AO4: =IF(ISNUMBER(X4),MIN(X4,AL4),"") | AP4: =INDEX(Compatibility!$D$2:$D$5,MATCH(AK4,Compatibility!$A$2:$A$5,0)) -> PB30, PBN30 (30A L14-30 inlet) | AQ4: =INDEX(Compatibility!$E$2:$E$5,MATCH(AK4,Compatibility!$A$2:$A$5,0)) -> XP3010GC, XP3025GC, XP3050GC, PC3040 (L14-30P to L14-30R) | AR4: =INDEX(Compatibility!$F$2:$F$5,MATCH(AK4,Compatibility!$A$2:$A$5,0)) -> 30A / 6 circuit: 306A, R306A (outdoor), 306C, 306D, 306CRK (kit); 30A / 10 circuit: 310C, 310D, 310CRK (kit), R310A (outdoor), 310CDKN (kit) | AS4: =INDEX(Compatibility!$G$2:$G$5,MATCH(AK4,Compatibility!$A$2:$A$5,0)) -> 30A 2-pole backfeed breaker (panel brand) + GenInterlock kit for panel | AT4: Floating | AU4: No | AV4: =IF(I4<>"Yes","120V only - extension cords / furnace switch",IF(AT4="Floating","Floating neutral: standard 2-pole transfer switch or interlock kit as-is",IF(AT4="Bonded",IF(AU4="Yes","Bonded neutral: have an electrician remove the bond (DuroMax instructions) for 2-pole switch / interlock, or use a neutral-switching (3-pole) switch","Bonded neutral, no unbond instructions published: neutral-switching (3-pole) switch - confirm with DuroMax"),"Neutral not stated - confirm with DuroMax"))) -> Floating neutral: standard 2-pole transfer switch or interlock kit as-is | AW4: "Neutral System | Floating" (manual p.72) | AX4: https://cdn.shopify.com/s/files/1/0613/1168/0689/files/XP5500HX_manual_revised_12012023_CARB_EPA_WEB.pdf | AZ4: 4-Stroke OHV | BA4: 210 | BB4: 3600 | BC4: Electric (rocker switch), recoil, remote | BD4: Yes | BE4: 10W-30 | BF4: 20.3 | BG4: Yes | BH4: Yes | BI4: No | BJ4: 120/240V | BK4: 60 | BM4: Yes | BN4: 12V SLA (included) | BO4: 4 | BP4: 25 L x 23 W x 22 H | BQ4: 128 | BR4: 131 | BS4: 69 | BT4: 5 Year | BX4: XP5500HX Generator, oil funnel, spark plug wrench, tool set, wheel & handle kit, propane regulator, owner's manual | BY4: https://www.duromaxpower.com/products/5500-watt-7-5-hp-portable-gas-electric-start-generator-with-co-alert | BZ4: https://cdn.shopify.com/s/files/1/0613/1168/0689/files/XP5500HX_001.png?v=1749582918 | CA4: Compare-at $799. USB = 1 USB-A + 1 USB-C. THD not listed. Described as RV/home backup ready; no transfer-switch wording. Handle mentions 7.5 HP.
A5: DuroMax | B5: XP10000X | C5: 10,000 Watt Gasoline Portable Generator w/ CO Alert | D5: Conventional open frame | E5: Gasoline | F5: No | G5: 799 | H5: Sold out / unavailable | I5: Yes | J5: 10000 | K5: 8500 | L5: 70.83 | M5: 35.42 | N5: 22 | O5: 10 | AC5: 4 | AD5: 1 | AE5: 0 | AF5: 1 | AG5: 1 | AH5: 0 | AI5: 0 | AJ5: Yes | AK5: =IF(N(AG5)>0,"14-50R (50A)",IF(N(AF5)>0,"L14-30R (30A)","None - 120V only")) -> 14-50R (50A) | AL5: =INDEX(Compatibility!$C$2:$C$5,MATCH(AK5,Compatibility!$A$2:$A$5,0)) -> 12000 | AM5: =IF(ISNUMBER(K5),MIN(K5,AL5),"") -> 8500 | AN5: =IF(ISNUMBER(Q5),MIN(Q5,AL5),"") | AO5: =IF(ISNUMBER(X5),MIN(X5,AL5),"") | AP5: =INDEX(Compatibility!$D$2:$D$5,MATCH(AK5,Compatibility!$A$2:$A$5,0)) -> XP50PB, XP50PBN, PB50, PBN50 (50A CS6375 inlet) | AQ5: =INDEX(Compatibility!$E$2:$E$5,MATCH(AK5,Compatibility!$A$2:$A$5,0)) -> XP5015GC, XP5025GC, XP5050GC, PC5020-14, PC5025-14M (14-50P to CS6364) | AR5: =INDEX(Compatibility!$F$2:$F$5,MATCH(AK5,Compatibility!$A$2:$A$5,0)) -> 50A / 10 circuit: R510A (outdoor), A510C, 510C, 510D; 50A / 6 circuit: 506C | AS5: =INDEX(Compatibility!$G$2:$G$5,MATCH(AK5,Compatibility!$A$2:$A$5,0)) -> 50A 2-pole backfeed breaker (panel brand) + GenInterlock kit for panel | AT5: Floating | AU5: No | AV5: =IF(I5<>"Yes","120V only - extension cords / furnace switch",IF(AT5="Floating","Floating neutral: standard 2-pole transfer switch or interlock kit as-is",IF(AT5="Bonded",IF(AU5="Yes","Bonded neutral: have an electrician remove the bond (DuroMax instructions) for 2-pole switch / interlock, or use a neutral-switching (3-pole) switch","Bonded neutral, no unbond instructions published: neutral-switching (3-pole) switch - confirm with DuroMax"),"Neutral not stated - confirm with DuroMax"))) -> Floating neutral: standard 2-pole transfer switch or interlock kit as-is | AW5: "Neutral System Floating" (manual p.64) | AX5: https://cdn.shopify.com/s/files/1/0613/1168/0689/files/XP10000X_manual_revised_07152022_WEB.pdf?v=1658848035 | AZ5: 4-Stroke OHV | BA5: 420 | BB5: 3600 | BC5: Electric (rocker switch), recoil | BE5: 10W-30 | BF5: 37.2 | BG5: Yes | BH5: Yes | BI5: No | BJ5: 120/240V | BK5: 60 | BM5: Yes | BN5: 12V SLA (included) | BO5: 8.3 | BP5: 29 L x 30 W x 26 H | BQ5: 220 | BR5: 228 | BS5: 72 | BT5: 5 Year | BV5: Yes | BX5: Oil funnel, spark plug wrench, tool set, wheel & handle kit, owner's manual | BY5: https://www.duromaxpower.com/products/duromax-xp10000x-10-000-watt-439cc-gas-portable-generator-with-co-alert | BZ5: https://cdn.shopify.com/s/files/1/0613/1168/0689/files/XP10000X_001.jpg?v=1749582881 | CA5: Compare-at $1,199. Spec table says 420cc but URL handle says 439cc. '50 State Emissions: No' (CARB inferred false). Transfer switch-ready 50A outlet; digital multimeter, hour meter, fuel gauge. THD and remote start not listed. Page showed no stock status; .js available=false.
A6: DuroMax | B6: XP11500EH | C6: 11,500 Watt Dual Fuel Portable Generator | D6: Conventional open frame | E6: Dual Fuel | F6: No | G6: 1299 | H6: Amazon exclusive | I6: Yes | J6: 11500 | K6: 9000 | L6: 75 | M6: 37.5 | N6: 20 | O6: 8 | P6: 10925 | Q6: 8550 | R6: 71.25 | S6: 45.52 | T6: 15 | U6: 6 | AC6: 2 | AD6: 1 | AE6: 0 | AF6: 1 | AG6: 1 | AH6: 0 | AJ6: Yes | AK6: =IF(N(AG6)>0,"14-50R (50A)",IF(N(AF6)>0,"L14-30R (30A)","None - 120V only")) -> 14-50R (50A) | AL6: =INDEX(Compatibility!$C$2:$C$5,MATCH(AK6,Compatibility!$A$2:$A$5,0)) -> 12000 | AM6: =IF(ISNUMBER(K6),MIN(K6,AL6),"") -> 9000 | AN6: =IF(ISNUMBER(Q6),MIN(Q6,AL6),"") -> 8550 | AO6: =IF(ISNUMBER(X6),MIN(X6,AL6),"") | AP6: =INDEX(Compatibility!$D$2:$D$5,MATCH(AK6,Compatibility!$A$2:$A$5,0)) -> XP50PB, XP50PBN, PB50, PBN50 (50A CS6375 inlet) | AQ6: =INDEX(Compatibility!$E$2:$E$5,MATCH(AK6,Compatibility!$A$2:$A$5,0)) -> XP5015GC, XP5025GC, XP5050GC, PC5020-14, PC5025-14M (14-50P to CS6364) | AR6: =INDEX(Compatibility!$F$2:$F$5,MATCH(AK6,Compatibility!$A$2:$A$5,0)) -> 50A / 10 circuit: R510A (outdoor), A510C, 510C, 510D; 50A / 6 circuit: 506C | AS6: =INDEX(Compatibility!$G$2:$G$5,MATCH(AK6,Compatibility!$A$2:$A$5,0)) -> 50A 2-pole backfeed breaker (panel brand) + GenInterlock kit for panel | AT6: Floating | AU6: No | AV6: =IF(I6<>"Yes","120V only - extension cords / furnace switch",IF(AT6="Floating","Floating neutral: standard 2-pole transfer switch or interlock kit as-is",IF(AT6="Bonded",IF(AU6="Yes","Bonded neutral: have an electrician remove the bond (DuroMax instructions) for 2-pole switch / interlock, or use a neutral-switching (3-pole) switch","Bonded neutral, no unbond instructions published: neutral-switching (3-pole) switch - confirm with DuroMax"),"Neutral not stated - confirm with DuroMax"))) -> Floating neutral: standard 2-pole transfer switch or interlock kit as-is | AW6: "Neutral System Floating" (manual p.68) | AX6: https://cdn.shopify.com/s/files/1/0613/1168/0689/files/XP11500EH_manual_revised_07262022_WEB.pdf?v=1659652695 | AZ6: 4-Stroke OHV | BA6: 457 | BB6: 3600 | BC6: Electric (rocker switch), recoil | BE6: 10W-30 | BF6: 40.5 | BH6: Yes | BJ6: 120/240V | BK6: 60 | BM6: Yes | BN6: 12V SLA (included) | BO6: 8.3 | BP6: 29 L x 30 W x 26 H | BQ6: 224 | BR6: 238 | BS6: 74 | BT6: 3 Year parts and technical service | BX6: Wheel & handle kit, propane hose & regulator (full list not stated) | BY6: https://www.duromaxpower.com/products/duromax-xp11500eh-11500-watt-electric-start-dual-fuel-hybrid-portable-generator | BZ6: https://cdn.shopify.com/s/files/1/0613/1168/0689/products/XP11500EH_1.png?v=1749582880 | CA6: LP 240V amps stated as 45.52 (likely site typo; 8550W/240V = 35.6) - recorded as stated. CO shutdown not listed (only automatic low oil shutdown). CARB/THD/12V not listed. Page says 'Available Exclusively At' Amazon; .js available=false. RV/home backup ready; digital multimeter, fuel gauge.
A7: DuroMax | B7: XP13000HXT | C7: 13,000 Watt Tri Fuel Portable HXT Generator w/ CO Alert | D7: Conventional open frame | E7: Tri Fuel | F7: No | G7: 1499 | H7: In stock | I7: Yes | J7: 13000 | K7: 10500 | L7: 87.5 | M7: 43.75 | N7: 17 | O7: 8.5 | P7: 12500 | Q7: 10000 | R7: 79.16 | S7: 39.58 | T7: 13 | U7: 6.5 | W7: 11250 | X7: 9000 | Y7: 70.83 | Z7: 35.42 | AA7: 6.0-9.0 | AB7: 225000 | AC7: 4 | AD7: 1 | AE7: 0 | AF7: 1 | AG7: 1 | AH7: 0 | AI7: 0 | AJ7: Yes | AK7: =IF(N(AG7)>0,"14-50R (50A)",IF(N(AF7)>0,"L14-30R (30A)","None - 120V only")) -> 14-50R (50A) | AL7: =INDEX(Compatibility!$C$2:$C$5,MATCH(AK7,Compatibility!$A$2:$A$5,0)) -> 12000 | AM7: =IF(ISNUMBER(K7),MIN(K7,AL7),"") -> 10500 | AN7: =IF(ISNUMBER(Q7),MIN(Q7,AL7),"") -> 10000 | AO7: =IF(ISNUMBER(X7),MIN(X7,AL7),"") -> 9000 | AP7: =INDEX(Compatibility!$D$2:$D$5,MATCH(AK7,Compatibility!$A$2:$A$5,0)) -> XP50PB, XP50PBN, PB50, PBN50 (50A CS6375 inlet) | AQ7: =INDEX(Compatibility!$E$2:$E$5,MATCH(AK7,Compatibility!$A$2:$A$5,0)) -> XP5015GC, XP5025GC, XP5050GC, PC5020-14, PC5025-14M (14-50P to CS6364) | AR7: =INDEX(Compatibility!$F$2:$F$5,MATCH(AK7,Compatibility!$A$2:$A$5,0)) -> 50A / 10 circuit: R510A (outdoor), A510C, 510C, 510D; 50A / 6 circuit: 506C | AS7: =INDEX(Compatibility!$G$2:$G$5,MATCH(AK7,Compatibility!$A$2:$A$5,0)) -> 50A 2-pole backfeed breaker (panel brand) + GenInterlock kit for panel | AT7: Floating | AU7: No | AV7: =IF(I7<>"Yes","120V only - extension cords / furnace switch",IF(AT7="Floating","Floating neutral: standard 2-pole transfer switch or interlock kit as-is",IF(AT7="Bonded",IF(AU7="Yes","Bonded neutral: have an electrician remove the bond (DuroMax instructions) for 2-pole switch / interlock, or use a neutral-switching (3-pole) switch","Bonded neutral, no unbond instructions published: neutral-switching (3-pole) switch - confirm with DuroMax"),"Neutral not stated - confirm with DuroMax"))) -> Floating neutral: standard 2-pole transfer switch or interlock kit as-is | AW7: "Neutral System Floating" (manual p.80) | AX7: https://cdn.shopify.com/s/files/1/0613/1168/0689/files/XP13000HXT_manual_revised_02072025_WEB.pdf?v=1755815346 | AZ7: 4-Stroke OHV | BA7: 500 | BB7: 3600 | BC7: Push button electric start, recoil backup | BD7: Yes | BE7: 10W-30 | BF7: 40.5 | BG7: Yes | BH7: Yes | BI7: No | BJ7: 120/240V | BK7: 60 | BL7: <5% | BM7: Yes | BN7: 12V SLA (included) | BO7: 8.3 | BP7: 30 L x 29 W x 26 H | BQ7: 240 | BR7: 246 | BS7: 74 | BT7: 5 Year parts and technical service | BX7: Generator, oil funnel, spark plug wrench, tool set, wheel & handle kit, 15ft natural gas hose, propane regulator, remote control, owner's manual | BY7: https://www.duromaxpower.com/products/duromax-xp13000hxt-13000-watt-500cc-tri-fuel-gas-propane-natural-gas-portable-generator-with-co-alert | BZ7: https://cdn.shopify.com/s/files/1/0613/1168/0689/files/XP13000HXT_001_d1629492-0800-4e8e-ab99-6ed654584d11.png?v=1775171669 | CA7: Compare-at $2,199. 'Home Backup Ready'; no explicit transfer-switch-ready spec (FAQ recommends transfer switch/interlock). LP 120V amps 79.16 differs from XP13000HX (83.13) for same wattage - as stated on site. Parallel/ECO not listed.
A8: DuroMax | B8: XP13000HX | C8: 13,000 Watt Dual Fuel Portable HX Generator w/ CO Alert | D8: Conventional open frame | E8: Dual Fuel | F8: No | G8: 1399 | H8: In stock | I8: Yes | J8: 13000 | K8: 10500 | L8: 87.5 | M8: 43.75 | N8: 17 | O8: 8.5 | P8: 12500 | Q8: 10000 | R8: 83.13 | S8: 41.56 | T8: 13 | U8: 6.5 | AC8: 4 | AD8: 1 | AE8: 0 | AF8: 1 | AG8: 1 | AH8: 0 | AI8: 0 | AJ8: Yes | AK8: =IF(N(AG8)>0,"14-50R (50A)",IF(N(AF8)>0,"L14-30R (30A)","None - 120V only")) -> 14-50R (50A) | AL8: =INDEX(Compatibility!$C$2:$C$5,MATCH(AK8,Compatibility!$A$2:$A$5,0)) -> 12000 | AM8: =IF(ISNUMBER(K8),MIN(K8,AL8),"") -> 10500 | AN8: =IF(ISNUMBER(Q8),MIN(Q8,AL8),"") -> 10000 | AO8: =IF(ISNUMBER(X8),MIN(X8,AL8),"") | AP8: =INDEX(Compatibility!$D$2:$D$5,MATCH(AK8,Compatibility!$A$2:$A$5,0)) -> XP50PB, XP50PBN, PB50, PBN50 (50A CS6375 inlet) | AQ8: =INDEX(Compatibility!$E$2:$E$5,MATCH(AK8,Compatibility!$A$2:$A$5,0)) -> XP5015GC, XP5025GC, XP5050GC, PC5020-14, PC5025-14M (14-50P to CS6364) | AR8: =INDEX(Compatibility!$F$2:$F$5,MATCH(AK8,Compatibility!$A$2:$A$5,0)) -> 50A / 10 circuit: R510A (outdoor), A510C, 510C, 510D; 50A / 6 circuit: 506C | AS8: =INDEX(Compatibility!$G$2:$G$5,MATCH(AK8,Compatibility!$A$2:$A$5,0)) -> 50A 2-pole backfeed breaker (panel brand) + GenInterlock kit for panel | AT8: Floating | AU8: No | AV8: =IF(I8<>"Yes","120V only - extension cords / furnace switch",IF(AT8="Floating","Floating neutral: standard 2-pole transfer switch or interlock kit as-is",IF(AT8="Bonded",IF(AU8="Yes","Bonded neutral: have an electrician remove the bond (DuroMax instructions) for 2-pole switch / interlock, or use a neutral-switching (3-pole) switch","Bonded neutral, no unbond instructions published: neutral-switching (3-pole) switch - confirm with DuroMax"),"Neutral not stated - confirm with DuroMax"))) -> Floating neutral: standard 2-pole transfer switch or interlock kit as-is | AW8: "Neutral System Floating" (manual p.68) | AX8: https://cdn.shopify.com/s/files/1/0613/1168/0689/files/XP13000HX_manual_revised_09162022_WEB.pdf?v=1663372666 | AZ8: 4-Stroke OHV | BA8: 500 | BB8: 3600 | BC8: Push button electric start, recoil backup | BD8: No | BE8: 10W-30 | BF8: 40.5 | BG8: Yes | BH8: Yes | BI8: No | BJ8: 120/240V | BK8: 60 | BL8: <5% | BM8: Yes | BN8: 12V SLA (included) | BO8: 8.3 | BP8: 30 L x 29 W x 26 H | BQ8: 240 | BR8: 246 | BS8: 74 | BT8: 5 Year parts and technical service | BX8: Generator, oil funnel, spark plug wrench, tool set, wheel & handle kit, propane regulator, owner's manual | BY8: https://www.duromaxpower.com/products/13000-watt-18-hp-portable-gas-electric-start-generator-with-co-alert | BZ8: https://cdn.shopify.com/s/files/1/0613/1168/0689/files/XP13000HX_001_52f77030-00ba-469f-9e97-22f772b348eb.png?v=1771880002 | CA8: Compare-at $1,799. Spec table: 'Remote Start No'. 'Home Backup Ready'; no explicit transfer-switch-ready spec row. Handle mentions 18 HP. Parallel/ECO not listed.
A9: DuroMax | B9: XP13000EH | C9: 13,000 Watt Dual Fuel Portable Generator | D9: Conventional open frame | E9: Dual Fuel | F9: No | G9: 1299 | H9: Sold out / unavailable | I9: Yes | J9: 13000 | K9: 10500 | L9: 87.5 | M9: 43.75 | N9: 17 | O9: 8 | P9: 12500 | Q9: 10000 | R9: 83.13 | S9: 41.56 | T9: 13 | U9: 6 | AC9: 2 | AD9: 1 | AE9: 0 | AF9: 1 | AG9: 1 | AH9: 0 | AI9: 1 | AJ9: Yes | AK9: =IF(N(AG9)>0,"14-50R (50A)",IF(N(AF9)>0,"L14-30R (30A)","None - 120V only")) -> 14-50R (50A) | AL9: =INDEX(Compatibility!$C$2:$C$5,MATCH(AK9,Compatibility!$A$2:$A$5,0)) -> 12000 | AM9: =IF(ISNUMBER(K9),MIN(K9,AL9),"") -> 10500 | AN9: =IF(ISNUMBER(Q9),MIN(Q9,AL9),"") -> 10000 | AO9: =IF(ISNUMBER(X9),MIN(X9,AL9),"") | AP9: =INDEX(Compatibility!$D$2:$D$5,MATCH(AK9,Compatibility!$A$2:$A$5,0)) -> XP50PB, XP50PBN, PB50, PBN50 (50A CS6375 inlet) | AQ9: =INDEX(Compatibility!$E$2:$E$5,MATCH(AK9,Compatibility!$A$2:$A$5,0)) -> XP5015GC, XP5025GC, XP5050GC, PC5020-14, PC5025-14M (14-50P to CS6364) | AR9: =INDEX(Compatibility!$F$2:$F$5,MATCH(AK9,Compatibility!$A$2:$A$5,0)) -> 50A / 10 circuit: R510A (outdoor), A510C, 510C, 510D; 50A / 6 circuit: 506C | AS9: =INDEX(Compatibility!$G$2:$G$5,MATCH(AK9,Compatibility!$A$2:$A$5,0)) -> 50A 2-pole backfeed breaker (panel brand) + GenInterlock kit for panel | AT9: Floating | AU9: No | AV9: =IF(I9<>"Yes","120V only - extension cords / furnace switch",IF(AT9="Floating","Floating neutral: standard 2-pole transfer switch or interlock kit as-is",IF(AT9="Bonded",IF(AU9="Yes","Bonded neutral: have an electrician remove the bond (DuroMax instructions) for 2-pole switch / interlock, or use a neutral-switching (3-pole) switch","Bonded neutral, no unbond instructions published: neutral-switching (3-pole) switch - confirm with DuroMax"),"Neutral not stated - confirm with DuroMax"))) -> Floating neutral: standard 2-pole transfer switch or interlock kit as-is | AW9: "Neutral System Floating" (manual p.68) | AX9: https://cdn.shopify.com/s/files/1/0613/1168/0689/files/XP13000EH_manual_rev06172022_WEB.pdf?v=1656093569 | AZ9: 4-Stroke OHV | BA9: 500 | BB9: 3600 | BC9: Push button electric start, recoil, remote | BD9: Yes | BE9: 10W-30 | BF9: 40.5 | BG9: Yes | BH9: Yes | BI9: No | BJ9: 120/240V | BK9: 60 | BM9: Yes | BN9: 12V SLA (included) | BO9: 8.3 | BP9: 29 L x 30 W x 26 H | BQ9: 234 | BR9: 248 | BS9: 74 | BT9: 3 Year parts and technical service | BV9: Yes | BX9: Generator, oil funnel, spark plug wrench, tool set, wheel & handle kit, propane hose & regulator, owner's manual | BY9: https://www.duromaxpower.com/products/duromax-xp13000eh-13000-watt-portable-hybrid-gas-propane-generator | BZ9: https://cdn.shopify.com/s/files/1/0613/1168/0689/products/XP13000EH_1.png?v=1749582853 | CA9: Compare-at $1,699. Page shows 'Sold Out'. 12V = '12v Automotive' outlet. Transfer switch-ready 50A outlet. THD not listed.
A10: DuroMax | B10: XP15500HXT | C10: 15,500 Watt Tri Fuel Portable HXT Generator w/ CO Alert | D10: Conventional open frame | E10: Tri Fuel | F10: No | G10: 2599 | H10: In stock | I10: Yes | J10: 15500 | K10: 12000 | L10: 100 | M10: 50 | N10: 15.8 | O10: 10.5 | P10: 14500 | Q10: 11500 | R10: 95.83 | S10: 47.92 | T10: 25.2 | U10: 10.8 | V10: 60 lb | W10: 13000 | X10: 10500 | Y10: 87.5 | Z10: 43.75 | AA10: 6-9 | AB10: 278000 | AC10: 4 | AF10: 1 | AG10: 2 | AJ10: Yes | AK10: =IF(N(AG10)>0,"14-50R (50A)",IF(N(AF10)>0,"L14-30R (30A)","None - 120V only")) -> 14-50R (50A) | AL10: =INDEX(Compatibility!$C$2:$C$5,MATCH(AK10,Compatibility!$A$2:$A$5,0)) -> 12000 | AM10: =IF(ISNUMBER(K10),MIN(K10,AL10),"") -> 12000 | AN10: =IF(ISNUMBER(Q10),MIN(Q10,AL10),"") -> 11500 | AO10: =IF(ISNUMBER(X10),MIN(X10,AL10),"") -> 10500 | AP10: =INDEX(Compatibility!$D$2:$D$5,MATCH(AK10,Compatibility!$A$2:$A$5,0)) -> XP50PB, XP50PBN, PB50, PBN50 (50A CS6375 inlet) | AQ10: =INDEX(Compatibility!$E$2:$E$5,MATCH(AK10,Compatibility!$A$2:$A$5,0)) -> XP5015GC, XP5025GC, XP5050GC, PC5020-14, PC5025-14M (14-50P to CS6364) | AR10: =INDEX(Compatibility!$F$2:$F$5,MATCH(AK10,Compatibility!$A$2:$A$5,0)) -> 50A / 10 circuit: R510A (outdoor), A510C, 510C, 510D; 50A / 6 circuit: 506C | AS10: =INDEX(Compatibility!$G$2:$G$5,MATCH(AK10,Compatibility!$A$2:$A$5,0)) -> 50A 2-pole backfeed breaker (panel brand) + GenInterlock kit for panel | AT10: Floating | AU10: No | AV10: =IF(I10<>"Yes","120V only - extension cords / furnace switch",IF(AT10="Floating","Floating neutral: standard 2-pole transfer switch or interlock kit as-is",IF(AT10="Bonded",IF(AU10="Yes","Bonded neutral: have an electrician remove the bond (DuroMax instructions) for 2-pole switch / interlock, or use a neutral-switching (3-pole) switch","Bonded neutral, no unbond instructions published: neutral-switching (3-pole) switch - confirm with DuroMax"),"Neutral not stated - confirm with DuroMax"))) -> Floating neutral: standard 2-pole transfer switch or interlock kit as-is | AW10: Floating - confirmed by DuroMax (Eddie), Sept 2026 | AZ10: 4-Stroke OHV | BA10: 550 | BB10: 3600 RPM ±100 RPM | BC10: Electric/Recoil/Remote | BD10: Yes | BE10: 10W-30 | BF10: 43.96 | BG10: Yes | BH10: Yes | BI10: No | BJ10: 120/240V | BK10: 60 | BL10: <5% | BN10: 12V AGM | BO10: 11.9 | BP10: 31" L x 28.25" W x 28.25" H | BQ10: 269 | BS10: 77 | BT10: 5 Year parts and technical service warranty | BV10: Yes | BW10: No | BX10: Generator, oil funnel, spark plug wrench, tool set, wheel kit, battery tender cord, natural gas hose, propane regulator, remote control, manual | BY10: https://www.duromaxpower.com/products/duromax-15500-watt-tri-fuel-portable-hxt-generator-w-co-alert | BZ10: https://cdn.shopify.com/s/files/1/0613/1168/0689/files/XP15500HXT_001.jpg?v=1789610380 | CA10: Compare-at $2,999. LP runtimes on 60 lb tank. '50 State Compliant No'/'Not For Sale to California'. Package weight 279.4 lbs. Idle Control No. Carburetor. Cast iron sleeve, copper windings, RV Ready. AVR/parallel not stated. Accessories list paraphrased by fetch tool.
A11: DuroMax | B11: XP15500HX | C11: 15,500 Watt Dual Fuel Portable HX Generator w/ CO Alert | D11: Conventional open frame | E11: Dual Fuel | F11: No | G11: 2299 | H11: In stock | I11: Yes | J11: 15500 | K11: 12000 | L11: 100 | M11: 50 | N11: 15.8 | O11: 10.5 | P11: 14500 | Q11: 11500 | R11: 95.8 | S11: 47.9 | T11: 25.2 | U11: 10.8 | V11: 60 lb | AC11: 4 | AF11: 1 | AG11: 2 | AJ11: Yes | AK11: =IF(N(AG11)>0,"14-50R (50A)",IF(N(AF11)>0,"L14-30R (30A)","None - 120V only")) -> 14-50R (50A) | AL11: =INDEX(Compatibility!$C$2:$C$5,MATCH(AK11,Compatibility!$A$2:$A$5,0)) -> 12000 | AM11: =IF(ISNUMBER(K11),MIN(K11,AL11),"") -> 12000 | AN11: =IF(ISNUMBER(Q11),MIN(Q11,AL11),"") -> 11500 | AO11: =IF(ISNUMBER(X11),MIN(X11,AL11),"") | AP11: =INDEX(Compatibility!$D$2:$D$5,MATCH(AK11,Compatibility!$A$2:$A$5,0)) -> XP50PB, XP50PBN, PB50, PBN50 (50A CS6375 inlet) | AQ11: =INDEX(Compatibility!$E$2:$E$5,MATCH(AK11,Compatibility!$A$2:$A$5,0)) -> XP5015GC, XP5025GC, XP5050GC, PC5020-14, PC5025-14M (14-50P to CS6364) | AR11: =INDEX(Compatibility!$F$2:$F$5,MATCH(AK11,Compatibility!$A$2:$A$5,0)) -> 50A / 10 circuit: R510A (outdoor), A510C, 510C, 510D; 50A / 6 circuit: 506C | AS11: =INDEX(Compatibility!$G$2:$G$5,MATCH(AK11,Compatibility!$A$2:$A$5,0)) -> 50A 2-pole backfeed breaker (panel brand) + GenInterlock kit for panel | AT11: Floating | AU11: No | AV11: =IF(I11<>"Yes","120V only - extension cords / furnace switch",IF(AT11="Floating","Floating neutral: standard 2-pole transfer switch or interlock kit as-is",IF(AT11="Bonded",IF(AU11="Yes","Bonded neutral: have an electrician remove the bond (DuroMax instructions) for 2-pole switch / interlock, or use a neutral-switching (3-pole) switch","Bonded neutral, no unbond instructions published: neutral-switching (3-pole) switch - confirm with DuroMax"),"Neutral not stated - confirm with DuroMax"))) -> Floating neutral: standard 2-pole transfer switch or interlock kit as-is | AW11: Floating - confirmed by DuroMax (Eddie), Sept 2026 | AZ11: 4-Stroke OHV | BA11: 550 | BB11: 3600 RPM ±100 RPM | BC11: Electric/Recoil/Remote | BD11: Yes | BE11: 10W-30 | BF11: 43.96 | BG11: Yes | BH11: Yes | BI11: No | BJ11: 120/240V | BK11: 60 | BL11: <5% | BN11: 12V AGM | BO11: 11.9 | BP11: 31" L x 29" W x 28.75" H | BQ11: 269 | BS11: 77 | BT11: 5 Year parts and technical service warranty | BV11: Yes | BW11: No | BX11: XP15500HX Generator, Oil Funnel, Spark Plug Wrench, Tool Set, Remote Control, Battery Tender Cord, Propane Regulator, Wheel & Handle Kit, and Owner's Manual | BY11: https://www.duromaxpower.com/products/duromax-15500-watt-dual-fuel-portable-hx-generator-w-co-alert | BZ11: https://cdn.shopify.com/s/files/1/0613/1168/0689/files/XP17500HX_001_420214b7-6bcd-4b7b-8495-f81ceed44982.jpg?v=1789608991 | CA11: 'Launch Exclusive Pricing' $2,299, compare-at $2,699. First image file is named XP17500HX (site reuses image). LP runtimes on 60 lb tank. 'Not For Sale to California'. Package weight 279.4 lbs. Idle Control No. Carburetor. AVR/parallel not stated. Dimensions differ slightly from XP15500HXT (29 in W vs 28.25 in).
A12: DuroMax | B12: XP15000HXT+ | C12: 15,000 Watt Electric Start Tri Fuel EFI Portable Generator | D12: Conventional open frame | E12: Tri Fuel | F12: Yes | G12: 3499 | H12: In stock | I12: Yes | J12: 15000 | K12: 12000 | L12: 100 | M12: 50 | N12: 17.9 | O12: 12 | P12: 14250 | Q12: 11400 | R12: 95 | S12: 47.5 | T12: 25 | U12: 13 | V12: 60 lb | W12: 13000 | X12: 10500 | Y12: 85.5 | Z12: 43.75 | AA12: 6.0-9.0 | AB12: 278000 | AC12: 4 | AD12: 0 | AF12: 0 | AG12: 2 | AJ12: Yes | AK12: =IF(N(AG12)>0,"14-50R (50A)",IF(N(AF12)>0,"L14-30R (30A)","None - 120V only")) -> 14-50R (50A) | AL12: =INDEX(Compatibility!$C$2:$C$5,MATCH(AK12,Compatibility!$A$2:$A$5,0)) -> 12000 | AM12: =IF(ISNUMBER(K12),MIN(K12,AL12),"") -> 12000 | AN12: =IF(ISNUMBER(Q12),MIN(Q12,AL12),"") -> 11400 | AO12: =IF(ISNUMBER(X12),MIN(X12,AL12),"") -> 10500 | AP12: =INDEX(Compatibility!$D$2:$D$5,MATCH(AK12,Compatibility!$A$2:$A$5,0)) -> XP50PB, XP50PBN, PB50, PBN50 (50A CS6375 inlet) | AQ12: =INDEX(Compatibility!$E$2:$E$5,MATCH(AK12,Compatibility!$A$2:$A$5,0)) -> XP5015GC, XP5025GC, XP5050GC, PC5020-14, PC5025-14M (14-50P to CS6364) | AR12: =INDEX(Compatibility!$F$2:$F$5,MATCH(AK12,Compatibility!$A$2:$A$5,0)) -> 50A / 10 circuit: R510A (outdoor), A510C, 510C, 510D; 50A / 6 circuit: 506C | AS12: =INDEX(Compatibility!$G$2:$G$5,MATCH(AK12,Compatibility!$A$2:$A$5,0)) -> 50A 2-pole backfeed breaker (panel brand) + GenInterlock kit for panel | AT12: Bonded | AU12: No | AV12: =IF(I12<>"Yes","120V only - extension cords / furnace switch",IF(AT12="Floating","Floating neutral: standard 2-pole transfer switch or interlock kit as-is",IF(AT12="Bonded",IF(AU12="Yes","Bonded neutral: have an electrician remove the bond (DuroMax instructions) for 2-pole switch / interlock, or use a neutral-switching (3-pole) switch","Bonded neutral, no unbond instructions published: neutral-switching (3-pole) switch - confirm with DuroMax"),"Neutral not stated - confirm with DuroMax"))) -> Bonded neutral, no unbond instructions published: neutral-switching (3-pole) switch - confirm with DuroMax | AW12: "Neutral System Bonded" (manual p.80) | AX12: https://cdn.shopify.com/s/files/1/0613/1168/0689/files/XP15000HXT__manual_03042025_WEB_1.pdf?v=1755808459 | AZ12: 4-Stroke OHV | BA12: 500 | BB12: 3600 RPM +/- 100 RPM | BC12: Push Button Electric/Recoil/Remote | BD12: Yes | BE12: 10W-30 | BF12: 37.2 | BG12: Yes | BH12: Yes | BI12: Yes | BJ12: 120/240V | BK12: 60 | BL12: <5% | BM12: Yes | BN12: 12V AGM | BO12: 8.3 | BP12: 29.5" L x 28" W x 26" H | BQ12: 237 | BS12: 74 | BT12: 5 Year parts and technical service warranty | BV12: Yes | BX12: Oil Funnel, Spark Plug Wrench, Tool Set, Wheel & Handle Kit, 25-Foot x 1/2-Inch Natural Gas Hose, Propane Regulator, Remote Control, Battery Tender | BY12: https://www.duromaxpower.com/products/duromax-15-000-watt-electric-start-tri-fuel-efi-portable-generator | BZ12: https://cdn.shopify.com/s/files/1/0613/1168/0689/files/XP15000HXT__001_Hero_3.png?v=1749582372 | CA12: Compare-at $3,799. EPA and CARB certified, 50 State Emissions Yes. Packaged weight 245 lbs (no wet weight). GFCI outlets 4. LP runtimes on 60 lb tank. NG 120V amps listed as 85.5 (inconsistent with 10,500W/120V=87.5; recorded as stated). Idle/eco and parallel not stated.
A13: DuroMax | B13: XP15000HX+ | C13: 15,000 Watt Electric Start Dual Fuel EFI Portable Generator | D13: Conventional open frame | E13: Dual Fuel | F13: Yes | G13: 2899 | H13: In stock | I13: Yes | J13: 15000 | K13: 12000 | L13: 100 | M13: 50 | N13: 17.9 | O13: 10 | P13: 14250 | Q13: 11400 | R13: 95 | S13: 47.5 | T13: 25 | U13: 13 | V13: 60 lb | AC13: 4 | AD13: 0 | AF13: 0 | AG13: 2 | AJ13: Yes | AK13: =IF(N(AG13)>0,"14-50R (50A)",IF(N(AF13)>0,"L14-30R (30A)","None - 120V only")) -> 14-50R (50A) | AL13: =INDEX(Compatibility!$C$2:$C$5,MATCH(AK13,Compatibility!$A$2:$A$5,0)) -> 12000 | AM13: =IF(ISNUMBER(K13),MIN(K13,AL13),"") -> 12000 | AN13: =IF(ISNUMBER(Q13),MIN(Q13,AL13),"") -> 11400 | AO13: =IF(ISNUMBER(X13),MIN(X13,AL13),"") | AP13: =INDEX(Compatibility!$D$2:$D$5,MATCH(AK13,Compatibility!$A$2:$A$5,0)) -> XP50PB, XP50PBN, PB50, PBN50 (50A CS6375 inlet) | AQ13: =INDEX(Compatibility!$E$2:$E$5,MATCH(AK13,Compatibility!$A$2:$A$5,0)) -> XP5015GC, XP5025GC, XP5050GC, PC5020-14, PC5025-14M (14-50P to CS6364) | AR13: =INDEX(Compatibility!$F$2:$F$5,MATCH(AK13,Compatibility!$A$2:$A$5,0)) -> 50A / 10 circuit: R510A (outdoor), A510C, 510C, 510D; 50A / 6 circuit: 506C | AS13: =INDEX(Compatibility!$G$2:$G$5,MATCH(AK13,Compatibility!$A$2:$A$5,0)) -> 50A 2-pole backfeed breaker (panel brand) + GenInterlock kit for panel | AT13: Bonded | AU13: Yes | AV13: =IF(I13<>"Yes","120V only - extension cords / furnace switch",IF(AT13="Floating","Floating neutral: standard 2-pole transfer switch or interlock kit as-is",IF(AT13="Bonded",IF(AU13="Yes","Bonded neutral: have an electrician remove the bond (DuroMax instructions) for 2-pole switch / interlock, or use a neutral-switching (3-pole) switch","Bonded neutral, no unbond instructions published: neutral-switching (3-pole) switch - confirm with DuroMax"),"Neutral not stated - confirm with DuroMax"))) -> Bonded neutral: have an electrician remove the bond (DuroMax instructions) for 2-pole switch / interlock, or use a neutral-switching (3-pole) switch | AW13: "Neutral System Bonded" (manual p.74) | AX13: https://cdn.shopify.com/s/files/1/0613/1168/0689/files/XP15000HX__manual_08272025_WEB.pdf?v=1756401571 | AY13: https://cdn.shopify.com/s/files/1/0613/1168/0689/files/XP15000HX__Remove_Bond_Instructions_WEB.pdf?v=1761163937 | AZ13: 4-Stroke OHV | BA13: 500 | BB13: 3600 RPM +/- 100 RPM | BC13: Push Button Electric/Recoil/Remote | BD13: Yes | BE13: 10W-30 | BF13: 37.2 | BG13: Yes | BH13: Yes | BI13: Yes | BJ13: 120/240V | BK13: 60 | BL13: <5% | BM13: Yes | BN13: 12V AGM | BO13: 8.3 | BP13: 29.5" L x 28" W x 26" H | BQ13: 237 | BS13: 74 | BT13: 5 Year parts and technical service warranty | BV13: Yes | BX13: Oil Funnel, Spark Plug Wrench, Tool Set, Wheel & Handle Kit, Propane Regulator, Remote Control, Battery Tender | BY13: https://www.duromaxpower.com/products/duromax-xp15000hx-15-000-watt-electric-start-dual-fuel-efi-portable-generator | BZ13: https://cdn.shopify.com/s/files/1/0613/1168/0689/files/XP15000HX__001.png?v=1754082484 | CA13: Page mentions sale from $3,299 (compare-at not in JSON fetch). Gas runtime @50% stated as 10 hrs (HXT+ sibling says 12 hrs; confirmed on re-fetch). EPA and CARB certified, 50 State Emissions Yes. Packaged weight 245 lbs. GFCI outlets 4. LP runtimes on 60 lb tank. Idle/eco and parallel not stated.
A14: DuroMax | B14: XP15000HXT | C14: 15,000 Watt Electric Start Tri Fuel Portable Generator | D14: Conventional open frame | E14: Tri Fuel | F14: No | G14: 2599 | H14: In stock | I14: Yes | J14: 15000 | K14: 12000 | L14: 100 | M14: 50 | N14: 17.9 | O14: 12 | P14: 14250 | Q14: 11400 | R14: 95 | S14: 47.5 | T14: 12.5 | U14: 8.5 | V14: 60 lb | W14: 12825 | X14: 10260 | Y14: 85.5 | Z14: 42.75 | AA14: 6.0-9.0 | AB14: 278000 | AC14: 10 | AD14: 1 | AF14: 1 | AG14: 1 | AJ14: Yes | AK14: =IF(N(AG14)>0,"14-50R (50A)",IF(N(AF14)>0,"L14-30R (30A)","None - 120V only")) -> 14-50R (50A) | AL14: =INDEX(Compatibility!$C$2:$C$5,MATCH(AK14,Compatibility!$A$2:$A$5,0)) -> 12000 | AM14: =IF(ISNUMBER(K14),MIN(K14,AL14),"") -> 12000 | AN14: =IF(ISNUMBER(Q14),MIN(Q14,AL14),"") -> 11400 | AO14: =IF(ISNUMBER(X14),MIN(X14,AL14),"") -> 10260 | AP14: =INDEX(Compatibility!$D$2:$D$5,MATCH(AK14,Compatibility!$A$2:$A$5,0)) -> XP50PB, XP50PBN, PB50, PBN50 (50A CS6375 inlet) | AQ14: =INDEX(Compatibility!$E$2:$E$5,MATCH(AK14,Compatibility!$A$2:$A$5,0)) -> XP5015GC, XP5025GC, XP5050GC, PC5020-14, PC5025-14M (14-50P to CS6364) | AR14: =INDEX(Compatibility!$F$2:$F$5,MATCH(AK14,Compatibility!$A$2:$A$5,0)) -> 50A / 10 circuit: R510A (outdoor), A510C, 510C, 510D; 50A / 6 circuit: 506C | AS14: =INDEX(Compatibility!$G$2:$G$5,MATCH(AK14,Compatibility!$A$2:$A$5,0)) -> 50A 2-pole backfeed breaker (panel brand) + GenInterlock kit for panel | AT14: Bonded | AU14: Yes | AV14: =IF(I14<>"Yes","120V only - extension cords / furnace switch",IF(AT14="Floating","Floating neutral: standard 2-pole transfer switch or interlock kit as-is",IF(AT14="Bonded",IF(AU14="Yes","Bonded neutral: have an electrician remove the bond (DuroMax instructions) for 2-pole switch / interlock, or use a neutral-switching (3-pole) switch","Bonded neutral, no unbond instructions published: neutral-switching (3-pole) switch - confirm with DuroMax"),"Neutral not stated - confirm with DuroMax"))) -> Bonded neutral: have an electrician remove the bond (DuroMax instructions) for 2-pole switch / interlock, or use a neutral-switching (3-pole) switch | AW14: "Neutral System Bonded" (manual p.80) | AX14: https://cdn.shopify.com/s/files/1/0613/1168/0689/files/XP15000HXT_manual_02072025_WEB.pdf?v=1755815346 | AY14: https://cdn.shopify.com/s/files/1/0613/1168/0689/files/XP15000HXT_Remove_Bond_Instructions.pdf?v=1786147971 | AZ14: 4-Stroke OHV | BA14: 670 | BB14: 3600 RPM ±100 RPM | BC14: Push Button Electric/Recoil/Remote | BD14: Yes | BE14: 10W-30 | BF14: 57.5 | BG14: Yes | BH14: Yes | BI14: No | BJ14: 120/240V | BK14: 60 | BL14: <5% | BM14: Yes | BN14: 12V AGM | BO14: 13.2 | BP14: 36" L x 33.2" W x 32" H | BQ14: 362 | BS14: 78 | BT14: 5 Year parts and technical service warranty | BV14: Yes | BX14: Generator, oil funnel, spark plug wrench, tool set, wheel & handle kit, 15-Foot x 3/4-Inch Natural Gas Hose, propane regulator, remote control, manual | BY14: https://www.duromaxpower.com/products/duromax-xp15000hxt-15-000-watt-electric-start-tri-fuel-portable-generator | BZ14: https://cdn.shopify.com/s/files/1/0613/1168/0689/files/XP15000HXT_001.jpg?v=1749582562 | CA14: Compare-at $2,999. CARB Certified No, 50 State Compliant No. Packaged weight 421 lbs. GFCI outlets 4. LP runtimes 12.5/8.5 hrs with 60 lb minimum tank. Carburetor. Idle Control spec reads 'Idle Control No Load Low Idle' - ambiguous (may mean feature is 'No Load Low Idle'), eco_mode left null. All metal construction, copper windings, RV Ready. Parallel not stated. Accessory list paraphrased by fetch tool.
A15: DuroMax | B15: XP15000HX | C15: 15,000 Watt Electric Start Dual Fuel Portable Generator | D15: Conventional open frame | E15: Dual Fuel | F15: No | G15: 2499 | H15: In stock | I15: Yes | J15: 15000 | K15: 12000 | L15: 100 | M15: 50 | N15: 17.9 | O15: 12 | P15: 14250 | Q15: 11400 | R15: 95 | S15: 47.5 | T15: 12.5 | U15: 8.5 | AC15: 10 | AD15: 1 | AF15: 1 | AG15: 1 | AJ15: Yes | AK15: =IF(N(AG15)>0,"14-50R (50A)",IF(N(AF15)>0,"L14-30R (30A)","None - 120V only")) -> 14-50R (50A) | AL15: =INDEX(Compatibility!$C$2:$C$5,MATCH(AK15,Compatibility!$A$2:$A$5,0)) -> 12000 | AM15: =IF(ISNUMBER(K15),MIN(K15,AL15),"") -> 12000 | AN15: =IF(ISNUMBER(Q15),MIN(Q15,AL15),"") -> 11400 | AO15: =IF(ISNUMBER(X15),MIN(X15,AL15),"") | AP15: =INDEX(Compatibility!$D$2:$D$5,MATCH(AK15,Compatibility!$A$2:$A$5,0)) -> XP50PB, XP50PBN, PB50, PBN50 (50A CS6375 inlet) | AQ15: =INDEX(Compatibility!$E$2:$E$5,MATCH(AK15,Compatibility!$A$2:$A$5,0)) -> XP5015GC, XP5025GC, XP5050GC, PC5020-14, PC5025-14M (14-50P to CS6364) | AR15: =INDEX(Compatibility!$F$2:$F$5,MATCH(AK15,Compatibility!$A$2:$A$5,0)) -> 50A / 10 circuit: R510A (outdoor), A510C, 510C, 510D; 50A / 6 circuit: 506C | AS15: =INDEX(Compatibility!$G$2:$G$5,MATCH(AK15,Compatibility!$A$2:$A$5,0)) -> 50A 2-pole backfeed breaker (panel brand) + GenInterlock kit for panel | AT15: Bonded | AU15: Yes | AV15: =IF(I15<>"Yes","120V only - extension cords / furnace switch",IF(AT15="Floating","Floating neutral: standard 2-pole transfer switch or interlock kit as-is",IF(AT15="Bonded",IF(AU15="Yes","Bonded neutral: have an electrician remove the bond (DuroMax instructions) for 2-pole switch / interlock, or use a neutral-switching (3-pole) switch","Bonded neutral, no unbond instructions published: neutral-switching (3-pole) switch - confirm with DuroMax"),"Neutral not stated - confirm with DuroMax"))) -> Bonded neutral: have an electrician remove the bond (DuroMax instructions) for 2-pole switch / interlock, or use a neutral-switching (3-pole) switch | AW15: "Neutral System Bonded" (manual p.74) | AX15: https://cdn.shopify.com/s/files/1/0613/1168/0689/files/XP15000HX_manual_12012023_EPA_CARB_version_WEB.pdf | AY15: https://cdn.shopify.com/s/files/1/0613/1168/0689/files/XP15000HX_Remove_Bond_Instructions.pdf?v=1786148129 | AZ15: 4-Stroke OHV | BA15: 670 | BB15: 3600 RPM ±100 RPM | BC15: Push Button Electric/Recoil/Remote | BD15: Yes | BE15: 10W-30 | BF15: 57.5 | BG15: Yes | BH15: Yes | BI15: No | BJ15: 120/240V | BL15: <5% | BM15: Yes | BN15: 12V AGM | BO15: 13.2 | BP15: 36" L x 33.2" W x 32" H | BQ15: 345 | BS15: 78 | BT15: 5 Year parts and technical service warranty | BV15: Yes | BX15: XP13000HX Generator Oil Funnel Spark Plug Wrench Tool Set Wheel & Handle Kit Propane Regulator Owner's Manual | BY15: https://www.duromaxpower.com/products/duromax-xp15000hx-15-000-watt-electric-start-dual-fuel-portable-generator | BZ15: https://cdn.shopify.com/s/files/1/0613/1168/0689/files/XP15000HX_001_f4c2fb68-68cc-4216-aac6-e6e023c75aaf.jpg?v=1749582565 | CA15: No compare-at price. Frequency not stated on page (null). CARB Certified No, 50 State Compliant No. Packaged weight 404 lbs. GFCI outlets 4. Mentions 'transfer switch-ready 50 amp outlet'. Accessories list verbatim says 'XP13000HX Generator' (site typo) and omits remote, though another fetch said remote control included and remote start is listed. Idle Control spec 'No Load Low Idle' ambiguous -> eco_mode null. Parallel not stated.
A16: DuroMax | B16: XP17500HXT | C16: 17,500 Watt Tri Fuel Portable HXT Generator w/ CO Alert | D16: Conventional open frame | E16: Tri Fuel | F16: No | G16: 2999 | H16: In stock | I16: Yes | J16: 17500 | K16: 13750 | L16: 114.6 | M16: 57.3 | N16: 15 | O16: 10 | P16: 16500 | Q16: 13000 | R16: 108.3 | S16: 54.2 | T16: 24 | U16: 10.3 | V16: 60 lb | W16: 14500 | X16: 11750 | Y16: 97.92 | Z16: 48.96 | AA16: 6-9 | AB16: 300000 | AC16: 4 | AF16: 1 | AG16: 2 | AJ16: Yes | AK16: =IF(N(AG16)>0,"14-50R (50A)",IF(N(AF16)>0,"L14-30R (30A)","None - 120V only")) -> 14-50R (50A) | AL16: =INDEX(Compatibility!$C$2:$C$5,MATCH(AK16,Compatibility!$A$2:$A$5,0)) -> 12000 | AM16: =IF(ISNUMBER(K16),MIN(K16,AL16),"") -> 12000 | AN16: =IF(ISNUMBER(Q16),MIN(Q16,AL16),"") -> 12000 | AO16: =IF(ISNUMBER(X16),MIN(X16,AL16),"") -> 11750 | AP16: =INDEX(Compatibility!$D$2:$D$5,MATCH(AK16,Compatibility!$A$2:$A$5,0)) -> XP50PB, XP50PBN, PB50, PBN50 (50A CS6375 inlet) | AQ16: =INDEX(Compatibility!$E$2:$E$5,MATCH(AK16,Compatibility!$A$2:$A$5,0)) -> XP5015GC, XP5025GC, XP5050GC, PC5020-14, PC5025-14M (14-50P to CS6364) | AR16: =INDEX(Compatibility!$F$2:$F$5,MATCH(AK16,Compatibility!$A$2:$A$5,0)) -> 50A / 10 circuit: R510A (outdoor), A510C, 510C, 510D; 50A / 6 circuit: 506C | AS16: =INDEX(Compatibility!$G$2:$G$5,MATCH(AK16,Compatibility!$A$2:$A$5,0)) -> 50A 2-pole backfeed breaker (panel brand) + GenInterlock kit for panel | AT16: Floating | AU16: No | AV16: =IF(I16<>"Yes","120V only - extension cords / furnace switch",IF(AT16="Floating","Floating neutral: standard 2-pole transfer switch or interlock kit as-is",IF(AT16="Bonded",IF(AU16="Yes","Bonded neutral: have an electrician remove the bond (DuroMax instructions) for 2-pole switch / interlock, or use a neutral-switching (3-pole) switch","Bonded neutral, no unbond instructions published: neutral-switching (3-pole) switch - confirm with DuroMax"),"Neutral not stated - confirm with DuroMax"))) -> Floating neutral: standard 2-pole transfer switch or interlock kit as-is | AW16: Floating - confirmed by DuroMax (Eddie), Sept 2026 | AZ16: 4-Stroke OHV | BA16: 600 | BB16: 3600 RPM ±100 RPM | BC16: Electric/Recoil/Remote | BD16: Yes | BE16: 10W-30 | BF16: 43.96 | BG16: Yes | BH16: Yes | BI16: No | BJ16: 120/240V | BK16: 60 | BL16: <5% | BN16: 12V AGM | BO16: 11.9 | BP16: 31" L x 28" W x 28.75" H | BQ16: 269 | BS16: 77 | BT16: 5 Year parts and technical service warranty | BV16: Yes | BW16: No | BX16: Propane Hose and Regulator, Natural Gas Hose with Quick Connect, Quick Pin Wheel Kit, Oil Funnel, Spark Plug Wrench, Remote Control, Battery Tender, Tool Set, Owner's Manual | BY16: https://www.duromaxpower.com/products/duromax-17500-watt-tri-fuel-portable-hxt-generator-w-co-alert | BZ16: https://cdn.shopify.com/s/files/1/0613/1168/0689/files/XP17500HXT_001_7a0b6916-e040-4c11-8814-ea1d1273ef6c.jpg?v=1789581239 | CA16: Compare-at $3,499. LP runtimes on 60 lb tank. 'Not For Sale to California'. Package weight 279.4 lbs (no wet weight listed). Idle Control No. Fuel delivery: Carburetor. Copper windings. AVR not stated. GFCI Yes (count not stated). Parallel: one fetch summary said 'parallel-ready (kits sold separately)' but a targeted re-fetch found it not stated in specs -> null, verify. L5-30R not listed.
A17: DuroMax | B17: XP17500HX | C17: 17,500 Watt Dual Fuel Portable HX Generator w/ CO Alert | D17: Conventional open frame | E17: Dual Fuel | F17: No | G17: 2699 | H17: In stock | I17: Yes | J17: 17500 | K17: 13750 | L17: 114.6 | M17: 57.3 | N17: 15 | O17: 10 | P17: 16500 | Q17: 13000 | R17: 108.3 | S17: 54.2 | T17: 24 | U17: 10.3 | V17: 60 lb | AC17: 4 | AF17: 1 | AG17: 2 | AJ17: Yes | AK17: =IF(N(AG17)>0,"14-50R (50A)",IF(N(AF17)>0,"L14-30R (30A)","None - 120V only")) -> 14-50R (50A) | AL17: =INDEX(Compatibility!$C$2:$C$5,MATCH(AK17,Compatibility!$A$2:$A$5,0)) -> 12000 | AM17: =IF(ISNUMBER(K17),MIN(K17,AL17),"") -> 12000 | AN17: =IF(ISNUMBER(Q17),MIN(Q17,AL17),"") -> 12000 | AO17: =IF(ISNUMBER(X17),MIN(X17,AL17),"") | AP17: =INDEX(Compatibility!$D$2:$D$5,MATCH(AK17,Compatibility!$A$2:$A$5,0)) -> XP50PB, XP50PBN, PB50, PBN50 (50A CS6375 inlet) | AQ17: =INDEX(Compatibility!$E$2:$E$5,MATCH(AK17,Compatibility!$A$2:$A$5,0)) -> XP5015GC, XP5025GC, XP5050GC, PC5020-14, PC5025-14M (14-50P to CS6364) | AR17: =INDEX(Compatibility!$F$2:$F$5,MATCH(AK17,Compatibility!$A$2:$A$5,0)) -> 50A / 10 circuit: R510A (outdoor), A510C, 510C, 510D; 50A / 6 circuit: 506C | AS17: =INDEX(Compatibility!$G$2:$G$5,MATCH(AK17,Compatibility!$A$2:$A$5,0)) -> 50A 2-pole backfeed breaker (panel brand) + GenInterlock kit for panel | AT17: Floating | AU17: No | AV17: =IF(I17<>"Yes","120V only - extension cords / furnace switch",IF(AT17="Floating","Floating neutral: standard 2-pole transfer switch or interlock kit as-is",IF(AT17="Bonded",IF(AU17="Yes","Bonded neutral: have an electrician remove the bond (DuroMax instructions) for 2-pole switch / interlock, or use a neutral-switching (3-pole) switch","Bonded neutral, no unbond instructions published: neutral-switching (3-pole) switch - confirm with DuroMax"),"Neutral not stated - confirm with DuroMax"))) -> Floating neutral: standard 2-pole transfer switch or interlock kit as-is | AW17: Floating - confirmed by DuroMax (Eddie), Sept 2026 | AZ17: 4-Stroke OHV | BA17: 600 | BB17: 3600 RPM ±100 RPM | BC17: Electric/Recoil/Remote | BD17: Yes | BE17: 10W-30 | BF17: 43.96 | BG17: Yes | BH17: Yes | BI17: No | BJ17: 120/240V | BK17: 60 | BL17: <5% | BN17: 12V AGM | BO17: 11.9 | BP17: 31" L x 28" W x 28.75" H | BQ17: 269 | BS17: 77 | BT17: 5 Year parts and technical service warranty | BV17: Yes | BW17: No | BX17: XP17500HX Generator, Oil Funnel, Spark Plug Wrench, Tool Set, Remote Control, Battery Tender Cord, Propane Regulator, Wheel & Handle Kit, and Owner's Manual | BY17: https://www.duromaxpower.com/products/duromax-17500-watt-dual-fuel-portable-hx-generator-w-co-alert | BZ17: https://cdn.shopify.com/s/files/1/0613/1168/0689/files/XP17500HX_001.jpg?v=1789581305 | CA17: No compare-at price. LP runtimes on 60 lb tank. 'Not For Sale to California'. Package weight 279.4 lbs. Idle Control No. Carburetor. RV Ready. AVR not stated. GFCI Yes (count not stated). Parallel not stated in specs (page mentions parallel kits sold separately as accessories).
A18: DuroMax | B18: XP2300iH | C18: 2,300 Watt Portable Dual Fuel Inverter Generator - Quiet, Low THD | D18: Inverter | E18: Dual Fuel | F18: No | G18: 649 | H18: In stock | I18: No (120V only) | J18: 2300 | K18: 1800 | L18: 15 | N18: 13 | O18: 7 | P18: 2150 | Q18: 1700 | R18: 14.16 | T18: 38 | U18: 18 | V18: 20 lb | AC18: 2 | AD18: 1 | AE18: 0 | AF18: 0 | AG18: 0 | AH18: 2 | AI18: 0 | AK18: =IF(N(AG18)>0,"14-50R (50A)",IF(N(AF18)>0,"L14-30R (30A)","None - 120V only")) -> None - 120V only | AL18: =INDEX(Compatibility!$C$2:$C$5,MATCH(AK18,Compatibility!$A$2:$A$5,0)) -> 0 | AM18: =IF(ISNUMBER(K18),MIN(K18,AL18),"") -> 0 | AN18: =IF(ISNUMBER(Q18),MIN(Q18,AL18),"") -> 0 | AO18: =IF(ISNUMBER(X18),MIN(X18,AL18),"") | AP18: =INDEX(Compatibility!$D$2:$D$5,MATCH(AK18,Compatibility!$A$2:$A$5,0)) -> PB31 / PBN31 (L5-30, 120V only) - single-leg, not whole panel | AQ18: =INDEX(Compatibility!$E$2:$E$5,MATCH(AK18,Compatibility!$A$2:$A$5,0)) -> Standard 5-15 / 5-20 extension cords (see Connection Guide gauge table) | AR18: =INDEX(Compatibility!$F$2:$F$5,MATCH(AK18,Compatibility!$A$2:$A$5,0)) -> TF151W (15A) / TF201W (20A) single-circuit furnace switch only | AS18: =INDEX(Compatibility!$G$2:$G$5,MATCH(AK18,Compatibility!$A$2:$A$5,0)) -> Not supported - no 240V outlet | AT18: Bonded | AU18: No | AV18: =IF(I18<>"Yes","120V only - extension cords / furnace switch",IF(AT18="Floating","Floating neutral: standard 2-pole transfer switch or interlock kit as-is",IF(AT18="Bonded",IF(AU18="Yes","Bonded neutral: have an electrician remove the bond (DuroMax instructions) for 2-pole switch / interlock, or use a neutral-switching (3-pole) switch","Bonded neutral, no unbond instructions published: neutral-switching (3-pole) switch - confirm with DuroMax"),"Neutral not stated - confirm with DuroMax"))) -> 120V only - extension cords / furnace switch | AW18: "Neutral System Bonded" (manual p.60) | AX18: https://cdn.shopify.com/s/files/1/0613/1168/0689/files/XP2300iH_manual_revised_04042024_EPA_CARB_WEB.pdf | AZ18: 4-Stroke OHV | BA18: 80 | BB18: 3600-5300 | BC18: Recoil / Remote | BD18: Yes | BE18: 10W-30 | BF18: 13 | BG18: Yes | BH18: Yes | BI18: No | BJ18: 120V | BK18: 60 | BL18: <3% | BM18: Yes | BO18: 1.1 | BP18: 22 x 14 x 20 | BQ18: 50.6 | BR18: 53 | BS18: 52 | BT18: 3 Year | BU18: Yes | BV18: No | BW18: Yes | BX18: Propane hose/regulator, oil funnel, spark plug wrench, parallel cable, owner's manual (wheel & handle kit listed as included) | BY18: https://www.duromaxpower.com/products/duromax-xp2300ih-2300-watt-80cc-dual-fuel-inverter-generator-with-co-alert | BZ18: https://cdn.shopify.com/s/files/1/0613/1168/0689/files/XP2300iHHeroTransparent.jpg?v=1749582822 | CA18: compare-at $799. RPM listed as 3600-5300 (string). USB = 1 USB-A + 1 USB-C. Site lists 'Remote Start: Yes' but no electric start/battery - verify. Eco = 'Demand Based Variable Idle'. RV Ready, CO Alert. Propane min 20 lb tank suggested. GFCI and 12V DC not listed. Not home-backup/transfer-switch listed (set false = not listed).
A19: DuroMax | B19: XP7000iH | C19: 7,000 Watt Portable Dual Fuel Inverter Generator - Quiet, Low THD | D19: Inverter | E19: Dual Fuel | F19: No | G19: 1699 | H19: Pre-order | I19: Yes | J19: 7000 | K19: 5500 | L19: 45.83 | M19: 22.92 | N19: 16 | O19: 8 | P19: 6650 | Q19: 5225 | R19: 43.54 | S19: 21.77 | T19: 26 | U19: 14 | V19: 00 lb | AC19: 2 | AD19: 0 | AE19: 0 | AF19: 1 | AG19: 0 | AH19: 0 | AI19: 0 | AJ19: Yes | AK19: =IF(N(AG19)>0,"14-50R (50A)",IF(N(AF19)>0,"L14-30R (30A)","None - 120V only")) -> L14-30R (30A) | AL19: =INDEX(Compatibility!$C$2:$C$5,MATCH(AK19,Compatibility!$A$2:$A$5,0)) -> 7200 | AM19: =IF(ISNUMBER(K19),MIN(K19,AL19),"") -> 5500 | AN19: =IF(ISNUMBER(Q19),MIN(Q19,AL19),"") -> 5225 | AO19: =IF(ISNUMBER(X19),MIN(X19,AL19),"") | AP19: =INDEX(Compatibility!$D$2:$D$5,MATCH(AK19,Compatibility!$A$2:$A$5,0)) -> PB30, PBN30 (30A L14-30 inlet) | AQ19: =INDEX(Compatibility!$E$2:$E$5,MATCH(AK19,Compatibility!$A$2:$A$5,0)) -> XP3010GC, XP3025GC, XP3050GC, PC3040 (L14-30P to L14-30R) | AR19: =INDEX(Compatibility!$F$2:$F$5,MATCH(AK19,Compatibility!$A$2:$A$5,0)) -> 30A / 6 circuit: 306A, R306A (outdoor), 306C, 306D, 306CRK (kit); 30A / 10 circuit: 310C, 310D, 310CRK (kit), R310A (outdoor), 310CDKN (kit) | AS19: =INDEX(Compatibility!$G$2:$G$5,MATCH(AK19,Compatibility!$A$2:$A$5,0)) -> 30A 2-pole backfeed breaker (panel brand) + GenInterlock kit for panel | AT19: Bonded | AU19: Yes | AV19: =IF(I19<>"Yes","120V only - extension cords / furnace switch",IF(AT19="Floating","Floating neutral: standard 2-pole transfer switch or interlock kit as-is",IF(AT19="Bonded",IF(AU19="Yes","Bonded neutral: have an electrician remove the bond (DuroMax instructions) for 2-pole switch / interlock, or use a neutral-switching (3-pole) switch","Bonded neutral, no unbond instructions published: neutral-switching (3-pole) switch - confirm with DuroMax"),"Neutral not stated - confirm with DuroMax"))) -> Bonded neutral: have an electrician remove the bond (DuroMax instructions) for 2-pole switch / interlock, or use a neutral-switching (3-pole) switch | AW19: "Neutral System Bonded" (manual p.72) | AX19: https://cdn.shopify.com/s/files/1/0613/1168/0689/files/XP7000iH_manual_revised_02162024_WEB.pdf?v=1714662622 | AY19: https://cdn.shopify.com/s/files/1/0613/1168/0689/files/XP7000iH_Inverters.pdf?v=1735255332 | AZ19: 4-Stroke OHV | BA19: 320 | BB19: 3600 | BC19: Push Button Electric / Recoil / Remote | BD19: Yes | BE19: 10W-30 | BF19: 23.7 | BG19: Yes | BH19: Yes | BI19: No | BJ19: 120/240V | BK19: 60 | BL19: <3% | BM19: Yes | BN19: 12V SLA (included) | BO19: 3 | BP19: 25.1 x 19.4 x 21.38 | BS19: 62 | BT19: 5 Year | BU19: Yes | BV19: Yes | BW19: Yes | BX19: Generator, propane hose with regulator, oil funnel, spark plug wrench, remote control, battery tender, owner's manual, wheel & handle kit | BY19: https://www.duromaxpower.com/products/duromax-xp7000ih-7000-watt-dual-fuel-portable-digital-inverter-generator | BZ19: https://cdn.shopify.com/s/files/1/0613/1168/0689/files/XP7000iH_001.png?v=1749582560 | CA19: compare-at $1,999. Page shows 'Pre-Order - Ships Week Of: 1/4/2027' although JSON available=true. Weight listed only as 147 lbs (dry vs wet unclear; recorded in notes, not fields). Propane runtimes listed per tank size 40/60/100 lb; lp_runtime values recorded are for 40 lb tank (26/39/43.33 @25%, 14/21/23.33 @50%). Eco = 'Demand Based Variable Idle'. Home Backup Ready via L14-30R.
A20: DuroMax | B20: XP7000iHT | C20: 7,000 Watt Portable Tri Fuel Inverter Generator - Quiet, Low THD | D20: Inverter | E20: Tri Fuel | F20: No | G20: 1799 | H20: In stock | I20: Yes | J20: 7000 | K20: 5500 | L20: 45.83 | M20: 22.92 | N20: 16 | O20: 8 | P20: 6650 | Q20: 5225 | R20: 43.54 | S20: 21.77 | T20: 26 | U20: 14 | V20: 00 lb | W20: 6000 | X20: 4750 | Y20: 39.58 | Z20: 19.79 | AA20: 6.0-9.0 | AB20: 121000 | AC20: 2 | AD20: 0 | AE20: 0 | AF20: 1 | AG20: 0 | AH20: 0 | AI20: 0 | AJ20: Yes | AK20: =IF(N(AG20)>0,"14-50R (50A)",IF(N(AF20)>0,"L14-30R (30A)","None - 120V only")) -> L14-30R (30A) | AL20: =INDEX(Compatibility!$C$2:$C$5,MATCH(AK20,Compatibility!$A$2:$A$5,0)) -> 7200 | AM20: =IF(ISNUMBER(K20),MIN(K20,AL20),"") -> 5500 | AN20: =IF(ISNUMBER(Q20),MIN(Q20,AL20),"") -> 5225 | AO20: =IF(ISNUMBER(X20),MIN(X20,AL20),"") -> 4750 | AP20: =INDEX(Compatibility!$D$2:$D$5,MATCH(AK20,Compatibility!$A$2:$A$5,0)) -> PB30, PBN30 (30A L14-30 inlet) | AQ20: =INDEX(Compatibility!$E$2:$E$5,MATCH(AK20,Compatibility!$A$2:$A$5,0)) -> XP3010GC, XP3025GC, XP3050GC, PC3040 (L14-30P to L14-30R) | AR20: =INDEX(Compatibility!$F$2:$F$5,MATCH(AK20,Compatibility!$A$2:$A$5,0)) -> 30A / 6 circuit: 306A, R306A (outdoor), 306C, 306D, 306CRK (kit); 30A / 10 circuit: 310C, 310D, 310CRK (kit), R310A (outdoor), 310CDKN (kit) | AS20: =INDEX(Compatibility!$G$2:$G$5,MATCH(AK20,Compatibility!$A$2:$A$5,0)) -> 30A 2-pole backfeed breaker (panel brand) + GenInterlock kit for panel | AT20: Bonded | AU20: Yes | AV20: =IF(I20<>"Yes","120V only - extension cords / furnace switch",IF(AT20="Floating","Floating neutral: standard 2-pole transfer switch or interlock kit as-is",IF(AT20="Bonded",IF(AU20="Yes","Bonded neutral: have an electrician remove the bond (DuroMax instructions) for 2-pole switch / interlock, or use a neutral-switching (3-pole) switch","Bonded neutral, no unbond instructions published: neutral-switching (3-pole) switch - confirm with DuroMax"),"Neutral not stated - confirm with DuroMax"))) -> Bonded neutral: have an electrician remove the bond (DuroMax instructions) for 2-pole switch / interlock, or use a neutral-switching (3-pole) switch | AW20: "Neutral System Bonded" (manual p.78) | AX20: https://cdn.shopify.com/s/files/1/0613/1168/0689/files/XP7000iHT_manual_revised_11102025_WEB.pdf?v=1762799463 | AY20: https://cdn.shopify.com/s/files/1/0613/1168/0689/files/XP7000iHT_removing_the_bond_instructions_WEB.pdf | AZ20: 4-Stroke OHV | BA20: 320 | BB20: 3600 | BC20: Push Button Electric / Recoil / Remote | BD20: Yes | BE20: 10W-30 | BF20: 23.7 | BG20: Yes | BH20: Yes | BI20: No | BJ20: 120/240V | BK20: 60 | BL20: <3% | BM20: Yes | BN20: 12V SLA (included) | BO20: 3 | BP20: 25.1 x 19.4 x 21.38 | BS20: 62 | BT20: 5 Year | BU20: Yes | BV20: Yes | BW20: Yes | BX20: XP7000iHT Generator, Propane Regulator, 15-Foot x 1/2-Inch Natural Gas Hose, Oil Funnel, Spark Plug Wrench, Remote Control, Battery Tender, Owner's Manual (wheel kit included) | BY20: https://www.duromaxpower.com/products/duromax-xp7000iht-7000-watt-portable-tri-fuel-inverter-generator-w-co-alert | BZ20: https://cdn.shopify.com/s/files/1/0613/1168/0689/files/XP7000iHT_001.png?v=1750803563 | CA20: compare-at $2,299. In stock. Weight listed only as 147 lbs (dry vs wet unclear). Propane runtimes listed per tank size 40/60/100 lb; lp_runtime values recorded are for 40 lb tank (26/39/43.33 @25%, 14/21/23.33 @50%). Eco = 'Demand Based Variable Idle'.
